2022-12-27 22:25:18,135 INFO    MainThread:23465 [internal.py:wandb_internal():92] W&B internal server running at pid: 23465, started at: 2022-12-27 22:25:18.135233
2022-12-27 22:25:18,136 INFO    WriterThread:23465 [datastore.py:open_for_write():77] open: /Users/stephennelson/Projects/Learning-Frustum-Proposals/preprocess/wandb/run-20221227_222516-nf505fc9/run-nf505fc9.wandb
2022-12-27 22:25:18,138 DEBUG   SenderThread:23465 [sender.py:send():235] send: header
2022-12-27 22:25:18,138 DEBUG   SenderThread:23465 [sender.py:send():235] send: run
2022-12-27 22:25:41,754 ERROR   SenderThread:23465 [internal_api.py:execute():144] 500 response executing GraphQL.
2022-12-27 22:25:41,755 ERROR   SenderThread:23465 [internal_api.py:execute():145] {"error":"internal database error"}
2022-12-27 22:25:41,755 ERROR   SenderThread:23465 [retry.py:__call__():126] Retry attempt failed:
Traceback (most recent call last):
  File "/opt/anaconda3/envs/thesis/lib/python3.8/site-packages/wandb/sdk/lib/retry.py", line 102, in __call__
    result = self._call_fn(*args, **kwargs)
  File "/opt/anaconda3/envs/thesis/lib/python3.8/site-packages/wandb/sdk/internal/internal_api.py", line 147, in execute
    six.reraise(*sys.exc_info())
  File "/opt/anaconda3/envs/thesis/lib/python3.8/site-packages/six.py", line 719, in reraise
    raise value
  File "/opt/anaconda3/envs/thesis/lib/python3.8/site-packages/wandb/sdk/internal/internal_api.py", line 141, in execute
    return self.client.execute(*args, **kwargs)
  File "/opt/anaconda3/envs/thesis/lib/python3.8/site-packages/wandb/vendor/gql-0.2.0/wandb_gql/client.py", line 52, in execute
    result = self._get_result(document, *args, **kwargs)
  File "/opt/anaconda3/envs/thesis/lib/python3.8/site-packages/wandb/vendor/gql-0.2.0/wandb_gql/client.py", line 60, in _get_result
    return self.transport.execute(document, *args, **kwargs)
  File "/opt/anaconda3/envs/thesis/lib/python3.8/site-packages/wandb/vendor/gql-0.2.0/wandb_gql/transport/requests.py", line 39, in execute
    request.raise_for_status()
  File "/opt/anaconda3/envs/thesis/lib/python3.8/site-packages/requests/models.py", line 960, in raise_for_status
    raise HTTPError(http_error_msg, response=self)
requests.exceptions.HTTPError: 500 Server Error: Internal Server Error for url: https://api.wandb.ai/graphql
2022-12-27 22:25:46,931 ERROR   SenderThread:23465 [internal_api.py:execute():144] 500 response executing GraphQL.
2022-12-27 22:25:46,931 ERROR   SenderThread:23465 [internal_api.py:execute():145] {"error":"internal database error"}
2022-12-27 22:25:47,066 DEBUG   HandlerThread:23465 [handler.py:handle_request():141] handle_request: shutdown
2022-12-27 22:25:47,066 INFO    HandlerThread:23465 [handler.py:finish():790] shutting down handler
2022-12-27 22:25:47,252 INFO    WriterThread:23465 [datastore.py:close():281] close: /Users/stephennelson/Projects/Learning-Frustum-Proposals/preprocess/wandb/run-20221227_222516-nf505fc9/run-nf505fc9.wandb
2022-12-27 22:25:56,915 ERROR   SenderThread:23465 [internal_api.py:execute():144] 500 response executing GraphQL.
2022-12-27 22:25:56,916 ERROR   SenderThread:23465 [internal_api.py:execute():145] {"error":"internal database error"}
